[2024-06-07T10:47:14.507+0000] {task_context_logger.py:104} ERROR - Executor reports task instance <TaskInstance: scrape_data_daily.scrape_and_upload_to_s3_task scheduled__2024-01-04T00:00:00+00:00 [queued]> finished (failed) although the task says it's queued. (Info: None) Was the task killed externally?
